Fatal Python error: init_import_site: Failed to import the site module
Python runtime state: initialized
Traceback (most recent call last):
  File "/Library/Developer/CommandLineTools/Library/Frameworks/Python3.framework/Versions/3.9/lib/python3.9/site.py", line 621, in <module>
    main()
  File "/Library/Developer/CommandLineTools/Library/Frameworks/Python3.framework/Versions/3.9/lib/python3.9/site.py", line 604, in main
    known_paths = venv(known_paths)
  File "/Library/Developer/CommandLineTools/Library/Frameworks/Python3.framework/Versions/3.9/lib/python3.9/site.py", line 522, in venv
    with open(virtual_conf, encoding='utf-8') as f:
PermissionError: [Errno 1] Operation not permitted: '/Users/saona/Documents/GitHub/Seguimiento/dashboard/pyvenv.cfg'
/Library/Developer/CommandLineTools/usr/bin/python3: can't open file '/Users/saona/Documents/GitHub/Seguimiento/alertas_cron.py': [Errno 1] Operation not permitted
Fatal Python error: init_import_site: Failed to import the site module
Python runtime state: initialized
Traceback (most recent call last):
  File "/Library/Developer/CommandLineTools/Library/Frameworks/Python3.framework/Versions/3.9/lib/python3.9/site.py", line 621, in <module>
    main()
  File "/Library/Developer/CommandLineTools/Library/Frameworks/Python3.framework/Versions/3.9/lib/python3.9/site.py", line 604, in main
    known_paths = venv(known_paths)
  File "/Library/Developer/CommandLineTools/Library/Frameworks/Python3.framework/Versions/3.9/lib/python3.9/site.py", line 522, in venv
    with open(virtual_conf, encoding='utf-8') as f:
PermissionError: [Errno 1] Operation not permitted: '/Users/saona/Documents/GitHub/Seguimiento/dashboard/pyvenv.cfg'
